Workbook

Sheet Checker
B4: Revenue | C4: =SUMIFS(cleaned_data!$F$2:$F$56,cleaned_data!$E$2:$E$56,Checker!B4) -> 9803882
B5: Spending | C5: =SUMIFS(cleaned_data!$F$2:$F$56,cleaned_data!$E$2:$E$56,Checker!B5) -> 10691929
B6: SURPLUS FROM "CLEANED DATA" | C6: =C4-C5 -> -888047
B7: SURPLUS FROM "RAW_DATA" | C7: ='2024_financial_report_raw_data'!B33 -> -888047
C8: =C6-C7 -> 0

Sheet cleaned_data
A1: sankey_5 | B1: sankey_4 | C1: sankey_3 | D1: sankey_2 | E1: sankey_1 | F1: value | G1: source
D2: Taxes | E2: revenue | F2: 4174298
D3: Payments in lieu of taxes | E3: revenue | F3: 287923
D4: Quota shares | E4: revenue | F4: 544237
D5: Service rendered | E5: revenue | F5: 2155564
D6: Fee Collection | E6: revenue | F6: 416493
D7: Fines and penalties | E7: revenue | F7: 214107
D8: Other Revenues | E8: revenue | F8: 159218
B9: Government of Canada | C9: Operating Activities | D9: Transfers | E9: revenue | F9: 31965 | G9: Note 19
B10: Government of Quebec | C10: Operating Activities | D10: Transfers | E10: revenue | F10: 742452 | G10: Note 19
B11: Communaute metropolitaine de Montreal | C11: Operating Activities | D11: Transfers | E11: revenue | F11: 68275 | G11: Note 19
A12: Gas tax program and the Quebec government contribution | B12: Government of Canada | C12: Investing Activities | D12: Transfers | E12: revenue | F12: 71892 | G12: Note 19
A13: Canada transfer programs - Quebec | B13: Government of Canada | C13: Investing Activities | D13: Transfers | E13: revenue | F13: 16651 | G13: Note 19
A14: Canada transfer programs - Municipality | B14: Government of Canada | C14: Investing Activities | D14: Transfers | E14: revenue | F14: 3633 | G14: Note 19
A15: Other | B15: Government of Canada | C15: Investing Activities | D15: Transfers | E15: revenue | F15: 16924 | G15: Note 19
A16: Government public transit assistance program | B16: Government of Quebec | C16: Investing Activities | D16: Transfers | E16: revenue | F16: 320597 | G16: Note 19
A17: Gas tax program and the Quebec government contribution | B17: Government of Quebec | C17: Investing Activities | D17: Transfers | E17: revenue | F17: 154803 | G17: Note 19
A18: Government Assistance Program for public transit infrastructure | B18: Government of Quebec | C18: Investing Activities | D18: Transfers | E18: revenue | F18: 3793 | G18: Note 19
A19: Canada transfer programs - Quebec | B19: Government of Quebec | C19: Investing Activities | D19: Transfers | E19: revenue | F19: 16651 | G19: Note 19
A20: Quebec transfer programs - Municipality | B20: Government of Quebec | C20: Investing Activities | D20: Transfers | E20: revenue | F20: 64532 | G20: Note 19
A21: Communaute metropolitaine de Montreal | B21: Other | C21: Investing Activities | D21: Transfers | E21: revenue | F21: 753 | G21: Note 19
A22: Other | B22: Other | C22: Investing Activities | D22: Transfers | E22: revenue | F22: =4361-2969 -> 1392 | G22: Note 19 - Combined with Gov of Quebec Other
C23: Restricted to the Sinking Fund | D23: Portfolio Investment Income | E23: revenue | F23: 91844 | G23: Note 20
C24: Unrestricted | D24: Portfolio Investment Income | E24: revenue | F24: 26677 | G24: Note 20
C25: Tax arrears | D25: Other Interest Income | E25: revenue | F25: 32678 | G25: Note 20
C26: Interest on cash and other interest | D26: Other Interest Income | E26: revenue | F26: 58518 | G26: Note 20
C27: Proceeds from disposal | D27: Tangible Capital Assets | E27: revenue | F27: 6465
C28: Loss on disposal / write-off | D28: Tangible Capital Assets | E28: revenue | F28: 24292
B29: Vehicles | C29: Amortization | D29: Tangible Capital Assets | E29: revenue | F29: 62275 | G29: See TCA net calculation tab
B30: Metro cars | C30: Amortization | D30: Tangible Capital Assets | E30: revenue | F30: 34980 | G30: See TCA net calculation tab
B31: Municipal administration less Eliminations | C31: General Administration | D31: Expenditure | E31: spending | F31: 810408
B32: Municipal administration less Eliminations | C32: Public Security | D32: Expenditure | E32: spending | F32: 1364228
B33: Municipal administration less Eliminations | C33: Transportation | D33: Expenditure | E33: spending | F33: 1527772
B34: Controlled Organizations | C34: Transportation | D34: Expenditure | E34: spending | F34: 2084821
B35: Municipal administration less Eliminations | C35: Environmental Hygiene | D35: Expenditure | E35: spending | F35: 684792
B36: Municipal administration less Eliminations | C36: Health and Welfare | D36: Expenditure | E36: spending | F36: 255728
B37: Controlled Organizations | C37: Health and Welfare | D37: Expenditure | E37: spending | F37: 77742
B38: Municipal administration less Eliminations | C38: Urban planning and Development | D38: Expenditure | E38: spending | F38: 326899
B39: Controlled Organizations | C39: Urban planning and Development | D39: Expenditure | E39: spending | F39: 3358
B40: Municipal administration less Eliminations | C40: Recreation and Culture | D40: Expenditure | E40: spending | F40: 922615
...

Sheet tables_for_summary
B2: Spending | C2: =SUMIFS(cleaned_data!$F$2:$F$56,cleaned_data!$E$2:$E$56,tables_for_summary!B2) -> 10691929
B3: Revenue | C3: =SUMIFS(cleaned_data!$F$2:$F$56,cleaned_data!$E$2:$E$56,tables_for_summary!B3) -> 9803882
B4: Net difference | C4: =C3-C2 -> -888047
B5: Tax Revenue | C5: 4174298
B6: Population (rounded) | C6: 1762949
B7: Spend Per Capita | C7: =C2/C6*1000 -> 6064.7977
B8: Property Tax Per Capita | C8: =C5/C6*1000 -> 2367.7928
B9: Total Employees | C9: 28000 | D9: States: Join the 28,000-strong employees of the city. | E9: https://montreal.ca/en/articles/five-reasons-to-work-city-montreal-2937#:~:text=Join%20the%2028%2C000%2Dstrong%20employees%20of%20the%20city.
B11: General Administration | C11: 810408 | D11: =C11/$C$2 -> 0.075796238
B12: Public Security | C12: 1364228 | D12: =C12/$C$2 -> 0.12759419
B13: Transportation | C13: 3612593 | D13: =C13/$C$2 -> 0.33788038
B14: Environmental Hygiene | C14: 684792 | D14: =C14/$C$2 -> 0.064047563
B15: Health and Welfare | C15: 333470 | D15: =C15/$C$2 -> 0.031188946
B16: Urban Planning and Development | C16: 330257 | D16: =C16/$C$2 -> 0.030888439
B17: Recreation and Culture | C17: 1006407 | D17: =C17/$C$2 -> 0.094127729

Sheet Revenue
A3: sankey_5 | B3: sankey_4 | C3: sankey_3 | D3: sankey_2 | E3: sankey_1 | F3: value | G3: source
D4: Taxes | E4: revenue | F4: 4174298
D5: Payments in lieu of taxes | E5: revenue | F5: 287923
D6: Quota shares | E6: revenue | F6: 544237
D7: Service rendered | E7: revenue | F7: 2155564
D8: Fee Collection | E8: revenue | F8: 416493
D9: Fines and penalties | E9: revenue | F9: 214107
D10: Other Revenues | E10: revenue | F10: 159218
B11: Government of Canada | C11: Operating Activities | D11: Transfers | E11: revenue | F11: 31965 | G11: Note 19
B12: Government of Quebec | C12: Operating Activities | D12: Transfers | E12: revenue | F12: 742452 | G12: Note 19
B13: Communaute metropolitaine de Montreal | C13: Operating Activities | D13: Transfers | E13: revenue | F13: 68275 | G13: Note 19
A14: Gas tax program and the Quebec government contribution | B14: Government of Canada | C14: Investing Activities | D14: Transfers | E14: revenue | F14: 71892 | G14: Note 19
A15: Canada transfer programs - Quebec | B15: Government of Canada | C15: Investing Activities | D15: Transfers | E15: revenue | F15: 16651 | G15: Note 19
A16: Canada transfer programs - Municipality | B16: Government of Canada | C16: Investing Activities | D16: Transfers | E16: revenue | F16: 3633 | G16: Note 19
A17: Other | B17: Government of Canada | C17: Investing Activities | D17: Transfers | E17: revenue | F17: 16924 | G17: Note 19
A18: Government public transit assistance program | B18: Government of Quebec | C18: Investing Activities | D18: Transfers | E18: revenue | F18: 320597 | G18: Note 19
A19: Gas tax program and the Quebec government contribution | B19: Government of Quebec | C19: Investing Activities | D19: Transfers | E19: revenue | F19: 154803 | G19: Note 19
A20: Government Assistance Program for public transit infrastructure | B20: Government of Quebec | C20: Investing Activities | D20: Transfers | E20: revenue | F20: 3793 | G20: Note 19
A21: Canada transfer programs - Quebec | B21: Government of Quebec | C21: Investing Activities | D21: Transfers | E21: revenue | F21: 16651 | G21: Note 19
A22: Quebec transfer programs - Municipality | B22: Government of Quebec | C22: Investing Activities | D22: Transfers | E22: revenue | F22: 64532 | G22: Note 19
A23: Communaute metropolitaine de Montreal | B23: Other | C23: Investing Activities | D23: Transfers | E23: revenue | F23: 753 | G23: Note 19
A24: Other | B24: Other | C24: Investing Activities | D24: Transfers | E24: revenue | F24: =4361-2969 -> 1392 | G24: Note 19 - Combined with Gov of Quebec Other
C25: Restricted to the Sinking Fund | D25: Portfolio Investment Income | E25: revenue | F25: 91844 | G25: Note 20
C26: Unrestricted | D26: Portfolio Investment Income | E26: revenue | F26: 26677 | G26: Note 20
C27: Tax arrears | D27: Other Interest Income | E27: revenue | F27: 32678 | G27: Note 20
C28: Interest on cash and other interest | D28: Other Interest Income | E28: revenue | F28: 58518 | G28: Note 20
C29: Proceeds from disposal | D29: Tangible Capital Assets | E29: revenue | F29: 6465
C30: Loss on disposal / write-off | D30: Tangible Capital Assets | E30: revenue | F30: 24292
B31: Vehicles | C31: Amortization | D31: Tangible Capital Assets | E31: revenue | F31: 62275 | G31: See TCA net calculation tab
B32: Metro cars | C32: Amortization | D32: Tangible Capital Assets | E32: revenue | F32: 34980 | G32: See TCA net calculation tab

Sheet Expenses
A1: sankey_5 | B1: sankey_4 | C1: sankey_3 | D1: sankey_2 | E1: sankey_1 | F1: value | G1: source
B2: Municipal administration less Eliminations | C2: General Administration | D2: Expenditure | E2: spending | F2: 810408
B3: Municipal administration less Eliminations | C3: Public Security | D3: Expenditure | E3: spending | F3: 1364228
B4: Municipal administration less Eliminations | C4: Transportation | D4: Expenditure | E4: spending | F4: 1527772
B5: Controlled Organizations | C5: Transportation | D5: Expenditure | E5: spending | F5: 2084821
B6: Municipal administration less Eliminations | C6: Environmental Hygiene | D6: Expenditure | E6: spending | F6: 684792
B7: Municipal administration less Eliminations | C7: Health and Welfare | D7: Expenditure | E7: spending | F7: 255728
B8: Controlled Organizations | C8: Health and Welfare | D8: Expenditure | E8: spending | F8: 77742
B9: Municipal administration less Eliminations | C9: Urban planning and Development | D9: Expenditure | E9: spending | F9: 326899
B10: Controlled Organizations | C10: Urban planning and Development | D10: Expenditure | E10: spending | F10: 3358
B11: Municipal administration less Eliminations | C11: Recreation and Culture | D11: Expenditure | E11: spending | F11: 922615
B12: Controlled Organizations | C12: Recreation and Culture | D12: Expenditure | E12: spending | F12: 83792
B13: Municipal administration less Eliminations | C13: Financing Expenses | D13: Expenditure | E13: spending | F13: 375578
B14: Controlled Organizations | C14: Financing Expenses | D14: Expenditure | E14: spending | F14: 196492
C15: Change in assets held for sale | D15: Non-Tangible Capital Assets | E15: spending | F15: 38132
C16: Change in inventories | D16: Non-Tangible Capital Assets | E16: spending | F16: 13648
C17: Change in other non-financial assets | D17: Non-Tangible Capital Assets | E17: spending | F17: 138936
C18: Net remeasurement losses for the year | D18: Non-Tangible Capital Assets | E18: spending | F18: 4140
C19: Infrastructures | D19: Tangible Capital Assets | E19: spending | F19: 831751 | G19: See TCA net calculation tab
C20: Metro System - Infrastructures | D20: Tangible Capital Assets | E20: spending | F20: 437653 | G20: See TCA net calculation tab
C21: Metro System - Tunnels | D21: Tangible Capital Assets | E21: spending | F21: 4418 | G21: See TCA net calculation tab
C22: Buildings | D22: Tangible Capital Assets | E22: spending | F22: 340173 | G22: See TCA net calculation tab
C23: Leasehold Improvements | D23: Tangible Capital Assets | E23: spending | F23: 18865 | G23: See TCA net calculation tab
C24: Office furniture and equipment | D24: Tangible Capital Assets | E24: spending | F24: 15910 | G24: See TCA net calculation tab
C25: Machinery, tools and equipment | D25: Tangible Capital Assets | E25: spending | F25: 11488 | G25: See TCA net calculation tab
C26: Land | D26: Tangible Capital Assets | E26: spending | F26: 113205 | G26: See TCA net calculation tab
C27: Other | D27: Tangible Capital Assets | E27: spending | F27: 9385 | G27: See TCA net calculation tab

Sheet tca_net_calculation
B4: TCA Category | C4: Difference | D4: Acquisitions | E4: Amortization | F4: Categorization | G4: Source
B5: Infrastructures | C5: =D5-E5 -> 831751 | D5: 1332632 | E5: 500881 | F5: spend | G5: Note 16
B6: Metro System - Infrastructures | C6: =D6-E6 -> 437653 | D6: 577939 | E6: 140286 | F6: spend | G6: Note 16
B7: Metro System - Tunnels | C7: =D7-E7 -> 4418 | D7: 7921 | E7: 3503 | F7: spend | G7: Note 16
B8: Metro cars | C8: =D8-E8 -> -34980 | D8: 21108 | E8: 56088 | F8: revenue | G8: Note 16
B9: Buildings | C9: =D9-E9 -> 340173 | D9: 464287 | E9: 124114 | F9: spend | G9: Note 16
B10: Leasehold Improvements | C10: =D10-E10 -> 18865 | D10: 35452 | E10: 16587 | F10: spend | G10: Note 16
B11: Vehicles | C11: =D11-E11 -> -62275 | D11: 65380 | E11: 127655 | F11: revenue | G11: Note 16
B12: Office furniture and equipment | C12: =D12-E12 -> 15910 | D12: 159406 | E12: 143496 | F12: spend | G12: Note 16
B13: Machinery, tools and equipment | C13: =D13-E13 -> 11488 | D13: 40644 | E13: 29156 | F13: spend | G13: Note 16
B14: Land | C14: =D14-E14 -> 113205 | D14: 113205 | F14: spend | G14: Note 16
B15: Other | C15: =D15-E15 -> 9385 | D15: 9385 | F15: spend | G15: Note 16
B16: Total | C16: =SUM(C5:C15) -> 1685593 | D16: =SUM(D5:D15) -> 2827359 | E16: =SUM(E5:E15) -> 1141766
C17: 1685593 | D17: ='2024_financial_report_raw_data'!B23 -> 2827359 | E17: ='2024_financial_report_raw_data'!B25 -> 1141766

Sheet 2024_financial_report_raw_data
A1: Statement of Operations | B1: 2024 | C1: Notes
A2: Taxes | B2: 4174298
A3: Payments in lieu of taxes | B3: 287923
A4: Quota shares | B4: 544237
A5: Transfers | B5: 1514313 | C5: 19
A6: Service rendered | B6: 2155564
A7: Fee Collection | B7: 416493
A8: Fines and penalties | B8: 214107
A9: Portfolio investment income | B9: 118521 | C9: 20
A10: Other Interest Income | B10: 91196 | C10: 20
A11: Other Revenues | B11: 159218
A12: Total Revenue | B12: =SUM(B2:B11) -> 9675870
A13: General Administration | B13: 810408
A14: Public Security | B14: 1364228
A15: Transportation | B15: 3612593
A16: Environmental Hygiene | B16: 684792
A17: Health and Welfare | B17: 333470
A18: Urban Planning and Development | B18: 330257
A19: Recreation and Culture | B19: 1006407
A20: Financing Expenses | B20: 572070
A21: Total Expenditure | B21: =SUM(B13:B20) -> 8714225
A22: Surplus | B22: =B12-B21 -> 961645
A23: Acquisition | B23: 2827359 | C23: 16 | D23: expend | E23: =B23-B25 -> 1685593
A24: Proceeds from disposal | B24: 6465 | D24: revenue
A25: Amortization | B25: 1141766 | C25: 16 | D25: revenue
A26: Loss on disposal / write-off | B26: 24292 | D26: revenue
A27: Total TCA | B27: =B23-B24-B25-B26 -> 1654836
A28: Change in assets held for sale | B28: 38132 | D28: spend
A29: Change in inventories | B29: 13648 | D29: spend
A30: Change in other non-financial assets | B30: 138936 | D30: spend
A31: Net remeasurement losses for the year | B31: 4140 | D31: spend
A32: Total in Non-Tangible Capital Assets | B32: =SUM(B28:B31) -> 194856
A33: Change in Net Debt | B33: =B22-B27-B32 -> -888047
A35: Schedule 2 - Consolidated Operations and Accumulated Operating Surplus Itemized by Organization
A36: Operations Breakdown
A37: Municipal administration | B37: 4205653
A38: Eliminations | B38: -31355
A39: Total Taxes | B39: =SUM(B37:B38) -> 4174298
A40: Municipal administration | B40: 287923
A41: Total Payments in lieu of taxes | B41: =B40 -> 287923
...

Sheet Sheet1
A1: Municipal administration | B1: 819901 | D1: Municipal administration less Eliminations | E1: General Administration | F1: =B1+B2 -> 810408
A2: Eliminations | B2: -9493 | D2: Municipal administration less Eliminations | E2: Public Security | F2: =B4+B5 -> 1364228
A3: Total General Administration | B3: =B1+B2 -> 810408 | D3: Municipal administration less Eliminations | E3: Transportation | F3: =B7+B9 -> 1527772
A4: Municipal administration | B4: 1364918 | D4: Controlled Organizations | E4: Transportation | F4: =B8 -> 2084821
A5: Eliminations | B5: -690 | D5: Municipal administration less Eliminations | E5: Environmental Hygiene | F5: =B11+B12 -> 684792
A6: Total Public Security | B6: =SUM(B4:B5) -> 1364228 | D6: Municipal administration less Eliminations | E6: Health and Welfare | F6: =B14+B16 -> 255728
A7: Municipal administration | B7: 1690205 | D7: Controlled Organizations | E7: Health and Welfare | F7: =B15 -> 77742
A8: Controlled Organizations | B8: 2084821 | D8: Municipal administration less Eliminations | E8: Urban planning and Development | F8: =B18+B20 -> 326899
A9: Eliminations | B9: -162433 | D9: Controlled Organizations | E9: Urban planning and Development | F9: =B19 -> 3358
A10: Total Transportation | B10: =SUM(B7:B9) -> 3612593 | D10: Municipal administration less Eliminations | E10: Recreation and Culture | F10: =B22+B24 -> 922615
A11: Municipal administration | B11: 686271 | D11: Controlled Organizations | E11: Recreation and Culture | F11: =B23 -> 83792
A12: Eliminations | B12: -1479 | D12: Municipal administration less Eliminations | E12: Financing Expenses | F12: =B26+B28 -> 375578
A13: Total Environmental Hygiene | B13: =SUM(B11:B12) -> 684792 | D13: Controlled Organizations | E13: Financing Expenses | F13: =B27 -> 196492
A14: Municipal administration | B14: 276433
A15: Controlled Organizations | B15: 77742
A16: Eliminations | B16: -20705
A17: Total Health and Welfare | B17: =SUM(B14:B16) -> 333470
A18: Municipal administration | B18: 330022
A19: Controlled Organizations | B19: 3358
A20: Eliminations | B20: -3123
A21: Total Urban planning and Development | B21: =SUM(B18:B20) -> 330257
A22: Municipal administration | B22: 962862
A23: Controlled Organizations | B23: 83792
A24: Eliminations | B24: -40247
A25: Total Recreation and Culture | B25: =SUM(B22:B24) -> 1006407
A26: Municipal administration | B26: 431203
A27: Controlled Organizations | B27: 196492
A28: Eliminations | B28: -55625
A29: Total Financing Expenses | B29: =SUM(B26:B28) -> 572070

Sheet miscellaneous
A3: Remuneration | B3: ='2024_financial_report_raw_data'!B116+'2024_financial_report_raw_data'!B120 -> 3150974
A4: Benefit Cost | B4: ='2024_financial_report_raw_data'!B123+'2024_financial_report_raw_data'!B126 -> 821580
A5: Transportation and Communication | B5: ='2024_financial_report_raw_data'!B129 -> 49702
A6: Professional Fees | B6: ='2024_financial_report_raw_data'!B133+'2024_financial_report_raw_data'!B137+'2024_financial_report_raw_data'!B141 -> 808219
A7: Leasing and repairs | B7: ='2024_financial_report_raw_data'!B145+'2024_financial_report_raw_data'!B149 -> 301259
A8: Durable Goods | B8: ='2024_financial_report_raw_data'!B154+'2024_financial_report_raw_data'!B151 -> 42040
A9: Non Durable Goods | B9: ='2024_financial_report_raw_data'!B158+'2024_financial_report_raw_data'!B162 -> 470966
A10: Financing Expenses | B10: ='2024_financial_report_raw_data'!B172+'2024_financial_report_raw_data'!B175+'2024_financial_report_raw_data'!B169+'2024_financial_report_raw_data'!B166 -> 572072
A11: Contributions to organizations | B11: ='2024_financial_report_raw_data'!B177+'2024_financial_report_raw_data'!B179+'2024_financial_report_raw_data'!B182+'2024_financial_report_raw_data'!B184+'2024_financial_report_raw_data'!B186+'2024_financial_report_raw_data'!B188+'2024_financial_report_raw_data'!B190+'2024_financial_report_raw_data'!B192+'2024_financial_report_raw_data'!B194+'2024_financial_report_raw_data'!B198 -> 1225119
A12: Total operations | B12: =SUM(B3:B11) -> 7441931
A13: Amortization of TCA | B13: ='2024_financial_report_raw_data'!B201 -> 1141766
A14: Loss of disposable / write off | B14: ='2024_financial_report_raw_data'!B204 -> 23907
A15: Other Objects | B15: ='2024_financial_report_raw_data'!B208 -> 106621
A16: Tota Investing | B16: =SUM(B13:B15) -> 1272294
B17: =B12+B16 -> 8714225
A18: Checker | B18: ='2024_financial_report_raw_data'!B21 -> 8714225 | D18: =B18-B12 -> 1272294
